{"version":3,"sources":["during.js"],"names":[],"mappings":"AAAA;;AAEA,OAAO,cAAP,CAAsB,OAAtB,EAA+B,YAA/B,EAA6C;AACzC,WAAO;AADkC,CAA7C;AAGA,QAAQ,OAAR,GAAkB,MAAlB;;AAEA,IAAI,QAAQ,QAAQ,aAAR,CAAZ;;AAEA,IAAI,SAAS,uBAAuB,KAAvB,CAAb;;AAEA,IAAI,YAAY,QAAQ,qBAAR,CAAhB;;AAEA,IAAI,aAAa,uBAAuB,SAAvB,CAAjB;;AAEA,SAAS,sBAAT,CAAgC,GAAhC,EAAqC;AAAE,WAAO,OAAO,IAAI,UAAX,GAAwB,GAAxB,GAA8B,EAAE,SAAS,GAAX,EAArC;AAAwD;;AAE/F;;;;;;;;;;;;;;;;;;;;;;;;;;;;;;;;;;;;;AAqCA,SAAS,MAAT,CAAgB,IAAhB,EAAsB,EAAtB,EAA0B,QAA1B,EAAoC;AAChC,eAAW,CAAC,GAAG,WAAW,OAAf,EAAwB,YAAY,OAAO,OAA3C,CAAX;;AAEA,aAAS,IAAT,CAAc,GAAd,EAAmB;AACf,YAAI,GAAJ,EAAS,OAAO,SAAS,GAAT,CAAP;AACT,aAAK,KAAL;AACH;;AAED,aAAS,KAAT,CAAe,GAAf,EAAoB,KAApB,EAA2B;AACvB,YAAI,GAAJ,EAAS,OAAO,SAAS,GAAT,CAAP;AACT,YAAI,CAAC,KAAL,EAAY,OAAO,SAAS,IAAT,CAAP;AACZ,WAAG,IAAH;AACH;;AAED,SAAK,KAAL;AACH;AACD,OAAO,OAAP,GAAiB,QAAQ,SAAR,CAAjB","file":"during-compiled.js","sourcesContent":["'use strict';\n\nObject.defineProperty(exports, \"__esModule\", {\n    value: true\n});\nexports.default = during;\n\nvar _noop = require('lodash/noop');\n\nvar _noop2 = _interopRequireDefault(_noop);\n\nvar _onlyOnce = require('./internal/onlyOnce');\n\nvar _onlyOnce2 = _interopRequireDefault(_onlyOnce);\n\nfunction _interopRequireDefault(obj) { return obj && obj.__esModule ? obj : { default: obj }; }\n\n/**\n * Like [`whilst`]{@link module:ControlFlow.whilst}, except the `test` is an asynchronous function that\n * is passed a callback in the form of `function (err, truth)`. If error is\n * passed to `test` or `fn`, the main callback is immediately called with the\n * value of the error.\n *\n * @name during\n * @static\n * @memberOf module:ControlFlow\n * @method\n * @see [async.whilst]{@link module:ControlFlow.whilst}\n * @category Control Flow\n * @param {Function} test - asynchronous truth test to perform before each\n * execution of `fn`. Invoked with (callback).\n * @param {Function} fn - A function which is called each time `test` passes.\n * The function is passed a `callback(err)`, which must be called once it has\n * completed with an optional `err` argument. Invoked with (callback).\n * @param {Function} [callback] - A callback which is called after the test\n * function has failed and repeated execution of `fn` has stopped. `callback`\n * will be passed an error, if one occured, otherwise `null`.\n * @example\n *\n * var count = 0;\n *\n * async.during(\n *     function (callback) {\n *         return callback(null, count < 5);\n *     },\n *     function (callback) {\n *         count++;\n *         setTimeout(callback, 1000);\n *     },\n *     function (err) {\n *         // 5 seconds have passed\n *     }\n * );\n */\nfunction during(test, fn, callback) {\n    callback = (0, _onlyOnce2.default)(callback || _noop2.default);\n\n    function next(err) {\n        if (err) return callback(err);\n        test(check);\n    }\n\n    function check(err, truth) {\n        if (err) return callback(err);\n        if (!truth) return callback(null);\n        fn(next);\n    }\n\n    test(check);\n}\nmodule.exports = exports['default'];"]}